Workbook

Sheet 問題集①
B2: 実際に出るとは限らんから気休め程度に！ Lets' Gooooo! 画像問題（コマンド問題）の資料が圧倒的に足りません
B3: CCST Networking 練習問題集
B4: 「あなたの回答」セルをクリック → ドロップダウンで A〜D を選択 → 自動で結果と解説が表示されるで！
B6: Q01 ／ 50
B7: IPv6アドレス 2001:0db8:0000:0016:0000:001b:2000:0056 の最も圧縮された有効な形式はどれか？
B8: A | C8: 2001:db8::16::1b:2:56
B9: B | C9: 2001:db8::16::1b:2000:56
B10: C | C10: 2001:db8:16::1b:2:56
B11: D | C11: 2001:db8:0:16::1b:2000:56
B12: あなたの回答
B13: 結果 | C13: =IF(C12="","← A〜Dを選んでや！",IF(C12="D","✅ 正解！ 素晴らしいで～！","❌ 不正解... 正解は D やで！")) -> ← A〜Dを選んでや！
B14: 解説 | C14: =IF(C12="","回答を選んでから解説が表示されるで！","正解は D やで！ 先頭のゼロを省略して、連続するゼログループを :: で置き換えるんやけど、:: は1箇所にしか使えへんルールがあるで！ → 2001:db8:0:16::1b:2000:56 が答えやで～") -> 回答を選んでから解説が表示されるで！
B16: Q02 ／ 50
B17: コマンド出力（CDP情報）
B19: 以下のコマンド出力を表示するCiscoコマンドはどれか？
B20: A | C20: show mac-address-table
B21: B | C21: show cdp neighbor
B22: C | C22: show inventory
B23: D | C23: show ip interface
B24: あなたの回答
B25: 結果 | C25: =IF(C24="","← A〜Dを選んでや！",IF(C24="B","✅ 正解！ 素晴らしいで～！","❌ 不正解... 正解は B やで！")) -> ← A〜Dを選んでや！
B26: 解説 | C26: =IF(C24="","回答を選んでから解説が表示されるで！","正解は B やで！ show cdp neighbor は隣接するCiscoデバイスの情報を表示するコマンドやで！ Capability Codes・Device ID・Local Interface・Holdtimeなどが表示されるのがCDPの特徴やで～") -> 回答を選んでから解説が表示されるで！
B28: Q03 ／ 50
B29: UDPセグメントのヘッダーに含まれる情報はどれか？
B30: A | C30: IPアドレス
B31: B | C31: シーケンス番号
B32: C | C32: ポート番号
B33: D | C33: MACアドレス
B34: あなたの回答
B35: 結果 | C35: =IF(C34="","← A〜Dを選んでや！",IF(C34="C","✅ 正解！ 素晴らしいで～！","❌ 不正解... 正解は C やで！")) -> ← A〜Dを選んでや！
B36: 解説 | C36: =IF(C34="","回答を選んでから解説が表示されるで！","正解は C やで！ UDPヘッダーには送信元・宛先のポート番号が入っとるで！ IPアドレスはIPヘッダー、MACアドレスはEthernetフレーム、シーケンス番号はTCPの話やで。") -> 回答を選んでから解説が表示されるで！
B38: Q04 ／ 50
B39: tracert 192.168.1.10 の出力
B41: 以下のtracertコマンド出力から何がわかるか？
B42: A | C42: ホップ3のルーターがパケットを転送していない
B43: B | C43: 192.168.1.10 はホップ3のFWでブロックされている
B44: C | C44: 192.168.1.10 のサーバーはネットワーク経由で到達可能
B45: D | C45: Webサーバーへのリクエストが遅延してタイムアウト
B46: あなたの回答
B47: 結果 | C47: =IF(C46="","← A〜Dを選んでや！",IF(C46="C","✅ 正解！ 素晴らしいで～！","❌ 不正解... 正解は C やで！")) -> ← A〜Dを選んでや！
...

Sheet 問題集②
B2: CCST Networking 練習問題集
B3: 「あなたの回答」セルをクリック → ドロップダウンで A〜D を選択 → 自動で結果と解説が表示されます
B5: Q01 ／ 50
B6: TCP/IPモデルの4層を上から正しく並べたものはどれか？
B7: A | C7: アプリケーション／トランスポート／インターネット／ネットワークインターフェース
B8: B | C8: アプリケーション／セッション／トランスポート／ネットワーク
B9: C | C9: アプリケーション／インターネット／トランスポート／物理
B10: D | C10: セッション／プレゼンテーション／データリンク／物理
B11: あなたの回答
B12: 結果 | C12: =IF(C11="","← A〜D を選択してください",IF(C11="A","✅ 正解！ 素晴らしいです！","❌ 不正解... 正解は A です！")) -> ← A〜D を選択してください
B13: 解説 | C13: =IF(C11="","回答を選択すると解説が表示されます","正解はAです。 TCP/IPモデルは上から「アプリケーション層→トランスポート層→インターネット層→ネットワークインターフェース層」の4層構成です。 OSIの7層モデルと混同しないよう注意しましょう。") -> 回答を選択すると解説が表示されます
B15: Q02 ／ 50
B16: OSIモデルでルーティング（IPアドレスを使ったパケット転送）を担当する層はどれか？
B17: A | C17: 第2層（データリンク層）
B18: B | C18: 第3層（ネットワーク層）
B19: C | C19: 第4層（トランスポート層）
B20: D | C20: 第7層（アプリケーション層）
B21: あなたの回答
B22: 結果 | C22: =IF(C21="","← A〜D を選択してください",IF(C21="B","✅ 正解！ 素晴らしいです！","❌ 不正解... 正解は B です！")) -> ← A〜D を選択してください
B23: 解説 | C23: =IF(C21="","回答を選択すると解説が表示されます","正解はBです。 IPアドレスを使ったルーティングはネットワーク層（第3層）の仕事です。 データリンク層はMACアドレス、トランスポート層はTCP/UDPを扱います。Layer 3 = ルーティングと覚えましょう。") -> 回答を選択すると解説が表示されます
B25: Q03 ／ 50
B26: 「フレーム」と「パケット」の説明として正しいのはどれか？
B27: A | C27: フレームはLayer 3、パケットはLayer 2のデータ単位
B28: B | C28: フレームはLayer 2、パケットはLayer 3のデータ単位
B29: C | C29: フレームとパケットは同義
B30: D | C30: パケットはLayer 1のデータ単位
B31: あなたの回答
B32: 結果 | C32: =IF(C31="","← A〜D を選択してください",IF(C31="B","✅ 正解！ 素晴らしいです！","❌ 不正解... 正解は B です！")) -> ← A〜D を選択してください
B33: 解説 | C33: =IF(C31="","回答を選択すると解説が表示されます","正解はBです。 フレームはデータリンク層（Layer 2）のデータ単位でMACアドレスを含みます。 パケットはネットワーク層（Layer 3）のデータ単位でIPアドレスを含みます。 Layer 2 = フレーム、Layer 3 = パケットと覚えましょう。") -> 回答を選択すると解説が表示されます
B35: Q04 ／ 50
B36: 帯域幅（Bandwidth）とスループット（Throughput）の説明として正しいのはどれか？
B37: A | C37: 帯域幅は実際の転送速度、スループットは理論上の最大速度
B38: B | C38: 帯域幅は理論上の最大速度、スループットは実際の転送速度
B39: C | C39: どちらも同じ意味で使われる
B40: D | C40: スループットはレイテンシーと同義
B41: あなたの回答
B42: 結果 | C42: =IF(C41="","← A〜D を選択してください",IF(C41="B","✅ 正解！ 素晴らしいです！","❌ 不正解... 正解は B です！")) -> ← A〜D を選択してください
B43: 解説 | C43: =IF(C41="","回答を選択すると解説が表示されます","正解はBです。 帯域幅は「最大で出せる速度（理論値）」、スループットは「実際に出ている速度（実測値）」です。 高速道路の速度制限が帯域幅、実際に走っている速度がスループットのイメージです。") -> 回答を選択すると解説が表示されます
B45: Q05 ／ 50
B46: 「低帯域幅はネットワーク遅延（レイテンシー）を増加させる可能性がある」という記述は正しいか？
...

Sheet 問題集③（余った問題）
B2: CCST Networking 練習問題集
B3: 「あなたの回答」セルをクリック → ドロップダウンで A〜D を選択 → 自動で結果と解説が表示されます
B5: Q01 ／ 50
B6: ネットワークトラフィックをIPアドレス・ポート番号・アプリケーションに基づいて許可または拒否するデバイスはどれか？
B7: A | C7: ファイアウォール
B8: B | C8: アクセスポイント
B9: C | C9: VPNゲートウェイ
B10: D | C10: 侵入検知システム（IDS）
B11: あなたの回答
B12: 結果 | C12: =IF(C11="","← A〜D を選択してください",IF(C11="A","✅ 正解！ 素晴らしいです！","❌ 不正解... 正解は A です！")) -> ← A〜D を選択してください
B13: 解説 | C13: =IF(C11="","回答を選択すると解説が表示されます","正解はAです。 ファイアウォールはIPアドレス・ポート番号・プロトコル・アプリケーションに基づいてトラフィックをフィルタリングします。 アクセスポイントは無線接続の提供、VPNゲートウェイは暗号化通信の確立、IDSは不正検知が主な役割です。") -> 回答を選択すると解説が表示されます
B15: Q02 ／ 50
B16: VLAN2のコンピューターからVLAN2外のアドレスにpingが届かない場合、エンジニアが設定すべきものはどれか？
B17: A | C17: 追加のVLAN
B18: B | C18: デフォルトルート
B19: C | C19: デフォルトゲートウェイ
B20: D | C20: スタティックルート
B21: あなたの回答
B22: 結果 | C22: =IF(C21="","← A〜D を選択してください",IF(C21="C","✅ 正解！ 素晴らしいです！","❌ 不正解... 正解は C です！")) -> ← A〜D を選択してください
B23: 解説 | C23: =IF(C21="","回答を選択すると解説が表示されます","正解はCです。 異なるVLAN間の通信には、デフォルトゲートウェイ（Layer 3デバイス）が必要です。 VLAN2のコンピューターがVLAN2外に通信するには、ルーターまたはLayer 3スイッチのIPアドレスをデフォルトゲートウェイとして設定する必要があります。") -> 回答を選択すると解説が表示されます
B25: Q03 ／ 50
B26: Layer 2スイッチのmanagement VLANインターフェースにIPアドレスを割り当てる目的はどれか？
B27: A | C27: TelnetまたはSSHでスイッチのCLIにアクセスできるようにするため
B28: B | C28: スイッチがDHCPサービスを提供できるようにするため
B29: C | C29: スイッチがデフォルトゲートウェイとして機能できるようにするため
B30: D | C30: スイッチがURLを解決できるようにするため
B31: あなたの回答
B32: 結果 | C32: =IF(C31="","← A〜D を選択してください",IF(C31="A","✅ 正解！ 素晴らしいです！","❌ 不正解... 正解は A です！")) -> ← A〜D を選択してください
B33: 解説 | C33: =IF(C31="","回答を選択すると解説が表示されます","正解はAです。 Layer 2スイッチのManagement VLAN（通常はVLAN 1）にIPアドレスを設定することで、ネットワーク経由でTelnetやSSHを使用してスイッチのCLIにリモートアクセスできるようになります。") -> 回答を選択すると解説が表示されます
B35: Q04 ／ 50
B36: 4つのトラブルチケットのうち最優先で対応すべきはどれか？ A: プリンターを別のネットワークジャックに移設 B: 会議室でオンラインウェビナー中、ビデオ会議機器がインターネット接続不可 C: クラウドアプリのレスポンスが通常より遅い D: カフェテリアの無線アクセスが1時間前から停止
B37: A | C37: A: プリンターの移設
B38: B | C38: B: ウェビナー中の接続不可
B39: C | C39: C: クラウドアプリの遅延
B40: D | C40: D: カフェテリアのWi-Fi停止
B41: あなたの回答
B42: 結果 | C42: =IF(C41="","← A〜D を選択してください",IF(C41="B","✅ 正解！ 素晴らしいです！","❌ 不正解... 正解は B です！")) -> ← A〜D を選択してください
B43: 解説 | C43: =IF(C41="","回答を選択すると解説が表示されます","正解はBです。 リアルタイムで進行中のオンラインウェビナーへの影響は即時対応が必要です。 トラブルシューティングの優先順位は「ビジネスへの影響度」と「緊急性」に基づいて判断します。進行中のイベントへの影響が最も高優先度です。") -> 回答を選択すると解説が表示されます
B45: Q05 ／ 50
B46: /27（CIDR表記）を表すサブネットマスクはどれか？
...

Sheet スコア集計
B2: スコア集計
B3: 項目 | C3: 問題集① | D3: 問題集② | E3: 問題集③（余った問題）
B4: 総問題数 | C4: 50 | D4: 50 | E4: 60
B5: 正解数 | C5: =COUNTIF('問題集①'!C:C,"✅*") -> 0 | D5: =COUNTIF('問題集②'!C:C,"✅*") -> 0 | E5: =COUNTIF('問題集③（余った問題）'!C:C,"✅*") -> 0
B6: 不正解数 | C6: =COUNTIF('問題集①'!C:C,"❌*") -> 0 | D6: =COUNTIF('問題集②'!C:C,"❌*") -> 0 | E6: =COUNTIF('問題集③（余った問題）'!C:C,"❌*") -> 0
B7: 未回答 | C7: =50-COUNTIF('問題集①'!C:C,"✅*")-COUNTIF('問題集①'!C:C,"❌*") -> 50 | D7: =50-COUNTIF('問題集②'!C:C,"✅*")-COUNTIF('問題集②'!C:C,"❌*") -> 50 | E7: =50-COUNTIF('問題集③（余った問題）'!C:C,"✅*")-COUNTIF('問題集③（余った問題）'!C:C,"❌*") -> 50
B8: 正答率 | C8: =IFERROR(COUNTIF('問題集①'!C:C,"✅*")/50,0) -> 0 | D8: =IFERROR(COUNTIF('問題集②'!C:C,"✅*")/50,0) -> 0 | E8: =IFERROR(COUNTIF('問題集③（余った問題）'!C:C,"✅*")/50,0) -> 0
B10: 参考問題サイト ：https://quizlet.com/1022618278/2025-updated-100-150-ccst-networking-exam-questions-flash-cards/ ：https://examsland.com/free-practice-test/ccst-networking ：https://www.testpreplab.com/CCST-Networking-free-practice-test/
